[2024-12-03T13:37:31.855+0000] {local_task_job_runner.py:120} INFO - ::group::Pre task execution logs
[2024-12-03T13:37:31.930+0000] {taskinstance.py:2073} INFO - Dependencies all met for dep_context=non-requeueable deps ti=<TaskInstance: etl_process_dag.calculate_top_products manual__2024-12-03T13:37:23.823829+00:00 [queued]>
[2024-12-03T13:37:31.951+0000] {taskinstance.py:2073} INFO - Dependencies all met for dep_context=requeueable deps ti=<TaskInstance: etl_process_dag.calculate_top_products manual__2024-12-03T13:37:23.823829+00:00 [queued]>
[2024-12-03T13:37:31.952+0000] {taskinstance.py:2303} INFO - Starting attempt 1 of 1
[2024-12-03T13:37:31.981+0000] {taskinstance.py:2327} INFO - Executing <Task(PostgresOperator): calculate_top_products> on 2024-12-03 13:37:23.823829+00:00
[2024-12-03T13:37:31.992+0000] {standard_task_runner.py:63} INFO - Started process 6168 to run task
[2024-12-03T13:37:31.997+0000] {standard_task_runner.py:90} INFO - Running: ['***', 'tasks', 'run', 'etl_process_dag', 'calculate_top_products', 'manual__2024-12-03T13:37:23.823829+00:00', '--job-id', '131', '--raw', '--subdir', 'DAGS_FOLDER/etl_sales.py', '--cfg-path', '/tmp/tmps3g_7j4a']
[2024-12-03T13:37:32.000+0000] {standard_task_runner.py:91} INFO - Job 131: Subtask calculate_top_products
[2024-12-03T13:37:32.093+0000] {task_command.py:426} INFO - Running <TaskInstance: etl_process_dag.calculate_top_products manual__2024-12-03T13:37:23.823829+00:00 [running]> on host a6f8f8b1d92d
[2024-12-03T13:37:32.521+0000] {taskinstance.py:2644} INFO - Exporting env vars: AIRFLOW_CTX_DAG_OWNER='k.norasit' AIRFLOW_CTX_DAG_ID='etl_process_dag' AIRFLOW_CTX_TASK_ID='calculate_top_products' AIRFLOW_CTX_EXECUTION_DATE='2024-12-03T13:37:23.823829+00:00' AIRFLOW_CTX_TRY_NUMBER='1' AIRFLOW_CTX_DAG_RUN_ID='manual__2024-12-03T13:37:23.823829+00:00'
[2024-12-03T13:37:32.523+0000] {taskinstance.py:430} INFO - ::endgroup::
[2024-12-03T13:37:32.542+0000] {sql.py:276} INFO - Executing: 
        INSERT INTO top_products_in_Chiangmai (order_date, rank_num, product_id, total_sales, total_quantity)
        SELECT order_date, RANK() OVER (PARTITION BY order_date ORDER BY SUM(quantity * amount) DESC) AS rank_num,
               product_id, SUM(quantity * amount), SUM(quantity)
        FROM transaction t
        JOIN user_info ui ON t.user_id = ui.user_id
        WHERE ui.location = 'Chiangmai'
        GROUP BY order_date, product_id
        HAVING rank_num <= 20;
        
[2024-12-03T13:37:32.554+0000] {base.py:84} INFO - Using connection ID 'postgres_default' for task execution.
[2024-12-03T13:37:32.567+0000] {base.py:84} INFO - Using connection ID 'postgres_default' for task execution.
[2024-12-03T13:37:32.592+0000] {sql.py:457} INFO - Running statement: 
        INSERT INTO top_products_in_Chiangmai (order_date, rank_num, product_id, total_sales, total_quantity)
        SELECT order_date, RANK() OVER (PARTITION BY order_date ORDER BY SUM(quantity * amount) DESC) AS rank_num,
               product_id, SUM(quantity * amount), SUM(quantity)
        FROM transaction t
        JOIN user_info ui ON t.user_id = ui.user_id
        WHERE ui.location = 'Chiangmai'
        GROUP BY order_date, product_id
        HAVING rank_num <= 20;
        , parameters: None
[2024-12-03T13:37:32.596+0000] {taskinstance.py:441} INFO - ::group::Post task execution logs
[2024-12-03T13:37:32.596+0000] {taskinstance.py:2890} ERROR - Task failed with exception
Traceback (most recent call last):
  File "/home/airflow/.local/lib/python3.9/site-packages/airflow/models/taskinstance.py", line 465, in _execute_task
    result = _execute_callable(context=context, **execute_callable_kwargs)
  File "/home/airflow/.local/lib/python3.9/site-packages/airflow/models/taskinstance.py", line 432, in _execute_callable
    return execute_callable(context=context, **execute_callable_kwargs)
  File "/home/airflow/.local/lib/python3.9/site-packages/airflow/models/baseoperator.py", line 400, in wrapper
    return func(self, *args, **kwargs)
  File "/home/airflow/.local/lib/python3.9/site-packages/airflow/providers/common/sql/operators/sql.py", line 282, in execute
    output = hook.run(
  File "/home/airflow/.local/lib/python3.9/site-packages/airflow/providers/common/sql/hooks/sql.py", line 404, in run
    self._run_command(cur, sql_statement, parameters)
  File "/home/airflow/.local/lib/python3.9/site-packages/airflow/providers/common/sql/hooks/sql.py", line 462, in _run_command
    cur.execute(sql_statement)
psycopg2.errors.UndefinedColumn: column "rank_num" does not exist
LINE 9:         HAVING rank_num <= 20;
                       ^
HINT:  There is a column named "rank_num" in table "top_products_in_chiangmai", but it cannot be referenced from this part of the query.

[2024-12-03T13:37:32.607+0000] {taskinstance.py:1205} INFO - Marking task as FAILED. dag_id=etl_process_dag, task_id=calculate_top_products, execution_date=20241203T133723, start_date=20241203T133731, end_date=20241203T133732
[2024-12-03T13:37:32.626+0000] {standard_task_runner.py:110} ERROR - Failed to execute job 131 for task calculate_top_products (column "rank_num" does not exist
LINE 9:         HAVING rank_num <= 20;
                       ^
HINT:  There is a column named "rank_num" in table "top_products_in_chiangmai", but it cannot be referenced from this part of the query.
; 6168)
[2024-12-03T13:37:32.657+0000] {local_task_job_runner.py:240} INFO - Task exited with return code 1
[2024-12-03T13:37:32.687+0000] {taskinstance.py:3482} INFO - 0 downstream tasks scheduled from follow-on schedule check
[2024-12-03T13:37:32.689+0000] {local_task_job_runner.py:222} INFO - ::endgroup::
