[2024-12-03T13:23:07.202+0000] {local_task_job_runner.py:120} INFO - ::group::Pre task execution logs
[2024-12-03T13:23:07.234+0000] {taskinstance.py:2073} INFO - Dependencies all met for dep_context=non-requeueable deps ti=<TaskInstance: etl_process_dag.load_user_info_data manual__2024-12-03T13:23:02.418490+00:00 [queued]>
[2024-12-03T13:23:07.243+0000] {taskinstance.py:2073} INFO - Dependencies all met for dep_context=requeueable deps ti=<TaskInstance: etl_process_dag.load_user_info_data manual__2024-12-03T13:23:02.418490+00:00 [queued]>
[2024-12-03T13:23:07.243+0000] {taskinstance.py:2303} INFO - Starting attempt 1 of 1
[2024-12-03T13:23:07.262+0000] {taskinstance.py:2327} INFO - Executing <Task(PythonOperator): load_user_info_data> on 2024-12-03 13:23:02.418490+00:00
[2024-12-03T13:23:07.267+0000] {standard_task_runner.py:63} INFO - Started process 5466 to run task
[2024-12-03T13:23:07.271+0000] {standard_task_runner.py:90} INFO - Running: ['***', 'tasks', 'run', 'etl_process_dag', 'load_user_info_data', 'manual__2024-12-03T13:23:02.418490+00:00', '--job-id', '116', '--raw', '--subdir', 'DAGS_FOLDER/etl_sales.py', '--cfg-path', '/tmp/tmpiyenwze9']
[2024-12-03T13:23:07.273+0000] {standard_task_runner.py:91} INFO - Job 116: Subtask load_user_info_data
[2024-12-03T13:23:07.321+0000] {task_command.py:426} INFO - Running <TaskInstance: etl_process_dag.load_user_info_data manual__2024-12-03T13:23:02.418490+00:00 [running]> on host a6f8f8b1d92d
[2024-12-03T13:23:07.577+0000] {taskinstance.py:2644} INFO - Exporting env vars: AIRFLOW_CTX_DAG_OWNER='k.norasit' AIRFLOW_CTX_DAG_ID='etl_process_dag' AIRFLOW_CTX_TASK_ID='load_user_info_data' AIRFLOW_CTX_EXECUTION_DATE='2024-12-03T13:23:02.418490+00:00' AIRFLOW_CTX_TRY_NUMBER='1' AIRFLOW_CTX_DAG_RUN_ID='manual__2024-12-03T13:23:02.418490+00:00'
[2024-12-03T13:23:07.578+0000] {taskinstance.py:430} INFO - ::endgroup::
[2024-12-03T13:23:07.762+0000] {taskinstance.py:441} INFO - ::group::Post task execution logs
[2024-12-03T13:23:07.763+0000] {taskinstance.py:2890} ERROR - Task failed with exception
Traceback (most recent call last):
  File "/home/airflow/.local/lib/python3.9/site-packages/sqlalchemy/engine/base.py", line 1890, in _execute_context
    self.dialect.do_executemany(
  File "/home/airflow/.local/lib/python3.9/site-packages/sqlalchemy/dialects/postgresql/psycopg2.py", line 982, in do_executemany
    context._psycopg2_fetched_rows = xtras.execute_values(
  File "/home/airflow/.local/lib/python3.9/site-packages/psycopg2/extras.py", line 1299, in execute_values
    cur.execute(b''.join(parts))
psycopg2.errors.UndefinedColumn: column "age" of relation "user_info" does not exist
LINE 1: INSERT INTO user_info (user_id, age, gender, location) VALUE...
                                        ^


The above exception was the direct cause of the following exception:

Traceback (most recent call last):
  File "/home/airflow/.local/lib/python3.9/site-packages/airflow/models/taskinstance.py", line 465, in _execute_task
    result = _execute_callable(context=context, **execute_callable_kwargs)
  File "/home/airflow/.local/lib/python3.9/site-packages/airflow/models/taskinstance.py", line 432, in _execute_callable
    return execute_callable(context=context, **execute_callable_kwargs)
  File "/home/airflow/.local/lib/python3.9/site-packages/airflow/models/baseoperator.py", line 400, in wrapper
    return func(self, *args, **kwargs)
  File "/home/airflow/.local/lib/python3.9/site-packages/airflow/operators/python.py", line 235, in execute
    return_value = self.execute_callable()
  File "/home/airflow/.local/lib/python3.9/site-packages/airflow/operators/python.py", line 252, in execute_callable
    return self.python_callable(*self.op_args, **self.op_kwargs)
  File "/opt/airflow/dags/etl_sales.py", line 41, in load_user_info_data_to_postgres
    df.to_sql(table_name, con=engine, if_exists='append', index=False)
  File "/home/airflow/.local/lib/python3.9/site-packages/pandas/util/_decorators.py", line 333, in wrapper
    return func(*args, **kwargs)
  File "/home/airflow/.local/lib/python3.9/site-packages/pandas/core/generic.py", line 3008, in to_sql
    return sql.to_sql(
  File "/home/airflow/.local/lib/python3.9/site-packages/pandas/io/sql.py", line 788, in to_sql
    return pandas_sql.to_sql(
  File "/home/airflow/.local/lib/python3.9/site-packages/pandas/io/sql.py", line 1958, in to_sql
    total_inserted = sql_engine.insert_records(
  File "/home/airflow/.local/lib/python3.9/site-packages/pandas/io/sql.py", line 1507, in insert_records
    raise err
  File "/home/airflow/.local/lib/python3.9/site-packages/pandas/io/sql.py", line 1498, in insert_records
    return table.insert(chunksize=chunksize, method=method)
  File "/home/airflow/.local/lib/python3.9/site-packages/pandas/io/sql.py", line 1059, in insert
    num_inserted = exec_insert(conn, keys, chunk_iter)
  File "/home/airflow/.local/lib/python3.9/site-packages/pandas/io/sql.py", line 951, in _execute_insert
    result = conn.execute(self.table.insert(), data)
  File "/home/airflow/.local/lib/python3.9/site-packages/sqlalchemy/engine/base.py", line 1385, in execute
    return meth(self, multiparams, params, _EMPTY_EXECUTION_OPTS)
  File "/home/airflow/.local/lib/python3.9/site-packages/sqlalchemy/sql/elements.py", line 334, in _execute_on_connection
    return connection._execute_clauseelement(
  File "/home/airflow/.local/lib/python3.9/site-packages/sqlalchemy/engine/base.py", line 1577, in _execute_clauseelement
    ret = self._execute_context(
  File "/home/airflow/.local/lib/python3.9/site-packages/sqlalchemy/engine/base.py", line 1953, in _execute_context
    self._handle_dbapi_exception(
  File "/home/airflow/.local/lib/python3.9/site-packages/sqlalchemy/engine/base.py", line 2134, in _handle_dbapi_exception
    util.raise_(
  File "/home/airflow/.local/lib/python3.9/site-packages/sqlalchemy/util/compat.py", line 211, in raise_
    raise exception
  File "/home/airflow/.local/lib/python3.9/site-packages/sqlalchemy/engine/base.py", line 1890, in _execute_context
    self.dialect.do_executemany(
  File "/home/airflow/.local/lib/python3.9/site-packages/sqlalchemy/dialects/postgresql/psycopg2.py", line 982, in do_executemany
    context._psycopg2_fetched_rows = xtras.execute_values(
  File "/home/airflow/.local/lib/python3.9/site-packages/psycopg2/extras.py", line 1299, in execute_values
    cur.execute(b''.join(parts))
sqlalchemy.exc.ProgrammingError: (psycopg2.errors.UndefinedColumn) column "age" of relation "user_info" does not exist
LINE 1: INSERT INTO user_info (user_id, age, gender, location) VALUE...
                                        ^

[SQL: INSERT INTO user_info (user_id, age, gender, location) VALUES (%(user_id)s, %(age)s, %(gender)s, %(location)s)]
[parameters: ({'user_id': 400, 'age': 28, 'gender': 'F', 'location': 'Khonkaen'}, {'user_id': 401, 'age': 55, 'gender': 'M', 'location': 'Khonkaen'}, {'user_id': 402, 'age': 30, 'gender': 'F', 'location': 'Chonburi'}, {'user_id': 403, 'age': 33, 'gender': 'F', 'location': 'Chonburi'}, {'user_id': 404, 'age': 19, 'gender': 'F', 'location': 'Chonburi'}, {'user_id': 405, 'age': 35, 'gender': 'F', 'location': 'Khonkaen'}, {'user_id': 406, 'age': 35, 'gender': 'F', 'location': 'Nan'}, {'user_id': 407, 'age': 59, 'gender': 'F', 'location': 'Bangkok'}  ... displaying 10 of 220 total bound parameter sets ...  {'user_id': 618, 'age': 39, 'gender': 'F', 'location': 'Nan'}, {'user_id': 619, 'age': 27, 'gender': 'F', 'location': 'Nan'})]
(Background on this error at: https://sqlalche.me/e/14/f405)
[2024-12-03T13:23:07.790+0000] {taskinstance.py:1205} INFO - Marking task as FAILED. dag_id=etl_process_dag, task_id=load_user_info_data, execution_date=20241203T132302, start_date=20241203T132307, end_date=20241203T132307
[2024-12-03T13:23:07.809+0000] {standard_task_runner.py:110} ERROR - Failed to execute job 116 for task load_user_info_data ((psycopg2.errors.UndefinedColumn) column "age" of relation "user_info" does not exist
LINE 1: INSERT INTO user_info (user_id, age, gender, location) VALUE...
                                        ^

[SQL: INSERT INTO user_info (user_id, age, gender, location) VALUES (%(user_id)s, %(age)s, %(gender)s, %(location)s)]
[parameters: ({'user_id': 400, 'age': 28, 'gender': 'F', 'location': 'Khonkaen'}, {'user_id': 401, 'age': 55, 'gender': 'M', 'location': 'Khonkaen'}, {'user_id': 402, 'age': 30, 'gender': 'F', 'location': 'Chonburi'}, {'user_id': 403, 'age': 33, 'gender': 'F', 'location': 'Chonburi'}, {'user_id': 404, 'age': 19, 'gender': 'F', 'location': 'Chonburi'}, {'user_id': 405, 'age': 35, 'gender': 'F', 'location': 'Khonkaen'}, {'user_id': 406, 'age': 35, 'gender': 'F', 'location': 'Nan'}, {'user_id': 407, 'age': 59, 'gender': 'F', 'location': 'Bangkok'}  ... displaying 10 of 220 total bound parameter sets ...  {'user_id': 618, 'age': 39, 'gender': 'F', 'location': 'Nan'}, {'user_id': 619, 'age': 27, 'gender': 'F', 'location': 'Nan'})]
(Background on this error at: https://sqlalche.me/e/14/f405); 5466)
[2024-12-03T13:23:07.844+0000] {local_task_job_runner.py:240} INFO - Task exited with return code 1
[2024-12-03T13:23:07.861+0000] {logging_mixin.py:188} WARNING - /home/***/.local/lib/python3.9/site-packages/***/models/baseoperator.py:1296 AirflowProviderDeprecationWarning: Call to deprecated class PostgresOperator. (Please use `***.providers.common.sql.operators.sql.SQLExecuteQueryOperator`.Also, you can provide `hook_params={'schema': <database>}`.)
[2024-12-03T13:23:07.880+0000] {taskinstance.py:3482} INFO - 0 downstream tasks scheduled from follow-on schedule check
[2024-12-03T13:23:07.885+0000] {local_task_job_runner.py:222} INFO - ::endgroup::
