[2024-12-03T12:47:38.409+0000] {local_task_job_runner.py:120} INFO - ::group::Pre task execution logs
[2024-12-03T12:47:38.441+0000] {taskinstance.py:2073} INFO - Dependencies all met for dep_context=non-requeueable deps ti=<TaskInstance: etl_process_dag.load_user_info_data manual__2024-12-03T12:47:33.234272+00:00 [queued]>
[2024-12-03T12:47:38.450+0000] {taskinstance.py:2073} INFO - Dependencies all met for dep_context=requeueable deps ti=<TaskInstance: etl_process_dag.load_user_info_data manual__2024-12-03T12:47:33.234272+00:00 [queued]>
[2024-12-03T12:47:38.450+0000] {taskinstance.py:2303} INFO - Starting attempt 1 of 1
[2024-12-03T12:47:38.461+0000] {taskinstance.py:2327} INFO - Executing <Task(PythonOperator): load_user_info_data> on 2024-12-03 12:47:33.234272+00:00
[2024-12-03T12:47:38.467+0000] {standard_task_runner.py:63} INFO - Started process 3670 to run task
[2024-12-03T12:47:38.470+0000] {standard_task_runner.py:90} INFO - Running: ['***', 'tasks', 'run', 'etl_process_dag', 'load_user_info_data', 'manual__2024-12-03T12:47:33.234272+00:00', '--job-id', '48', '--raw', '--subdir', 'DAGS_FOLDER/etl_sales.py', '--cfg-path', '/tmp/tmppuztxu37']
[2024-12-03T12:47:38.473+0000] {standard_task_runner.py:91} INFO - Job 48: Subtask load_user_info_data
[2024-12-03T12:47:38.522+0000] {task_command.py:426} INFO - Running <TaskInstance: etl_process_dag.load_user_info_data manual__2024-12-03T12:47:33.234272+00:00 [running]> on host a6f8f8b1d92d
[2024-12-03T12:47:38.778+0000] {taskinstance.py:2644} INFO - Exporting env vars: AIRFLOW_CTX_DAG_OWNER='k.norasit' AIRFLOW_CTX_DAG_ID='etl_process_dag' AIRFLOW_CTX_TASK_ID='load_user_info_data' AIRFLOW_CTX_EXECUTION_DATE='2024-12-03T12:47:33.234272+00:00' AIRFLOW_CTX_TRY_NUMBER='1' AIRFLOW_CTX_DAG_RUN_ID='manual__2024-12-03T12:47:33.234272+00:00'
[2024-12-03T12:47:38.779+0000] {taskinstance.py:430} INFO - ::endgroup::
[2024-12-03T12:47:38.893+0000] {logging_mixin.py:188} INFO - Loaded DataFrame for user_info.csv: 
   user_id  age gender  location
0      400   28      F  Khonkaen
1      401   55      M  Khonkaen
2      402   30      F  Chonburi
3      403   33      F  Chonburi
4      404   19      F  Chonburi
[2024-12-03T12:47:38.908+0000] {taskinstance.py:441} INFO - ::group::Post task execution logs
[2024-12-03T12:47:38.908+0000] {taskinstance.py:2890} ERROR - Task failed with exception
Traceback (most recent call last):
  File "/home/airflow/.local/lib/python3.9/site-packages/sqlalchemy/engine/base.py", line 3371, in _wrap_pool_connect
    return fn()
  File "/home/airflow/.local/lib/python3.9/site-packages/sqlalchemy/pool/base.py", line 327, in connect
    return _ConnectionFairy._checkout(self)
  File "/home/airflow/.local/lib/python3.9/site-packages/sqlalchemy/pool/base.py", line 894, in _checkout
    fairy = _ConnectionRecord.checkout(pool)
  File "/home/airflow/.local/lib/python3.9/site-packages/sqlalchemy/pool/base.py", line 493, in checkout
    rec = pool._do_get()
  File "/home/airflow/.local/lib/python3.9/site-packages/sqlalchemy/pool/impl.py", line 146, in _do_get
    self._dec_overflow()
  File "/home/airflow/.local/lib/python3.9/site-packages/sqlalchemy/util/langhelpers.py", line 70, in __exit__
    compat.raise_(
  File "/home/airflow/.local/lib/python3.9/site-packages/sqlalchemy/util/compat.py", line 211, in raise_
    raise exception
  File "/home/airflow/.local/lib/python3.9/site-packages/sqlalchemy/pool/impl.py", line 143, in _do_get
    return self._create_connection()
  File "/home/airflow/.local/lib/python3.9/site-packages/sqlalchemy/pool/base.py", line 273, in _create_connection
    return _ConnectionRecord(self)
  File "/home/airflow/.local/lib/python3.9/site-packages/sqlalchemy/pool/base.py", line 388, in __init__
    self.__connect()
  File "/home/airflow/.local/lib/python3.9/site-packages/sqlalchemy/pool/base.py", line 691, in __connect
    pool.logger.debug("Error on connect(): %s", e)
  File "/home/airflow/.local/lib/python3.9/site-packages/sqlalchemy/util/langhelpers.py", line 70, in __exit__
    compat.raise_(
  File "/home/airflow/.local/lib/python3.9/site-packages/sqlalchemy/util/compat.py", line 211, in raise_
    raise exception
  File "/home/airflow/.local/lib/python3.9/site-packages/sqlalchemy/pool/base.py", line 686, in __connect
    self.dbapi_connection = connection = pool._invoke_creator(self)
  File "/home/airflow/.local/lib/python3.9/site-packages/sqlalchemy/engine/create.py", line 574, in connect
    return dialect.connect(*cargs, **cparams)
  File "/home/airflow/.local/lib/python3.9/site-packages/sqlalchemy/engine/default.py", line 598, in connect
    return self.dbapi.connect(*cargs, **cparams)
  File "/home/airflow/.local/lib/python3.9/site-packages/psycopg2/__init__.py", line 122, in connect
    conn = _connect(dsn, connection_factory=connection_factory, **kwasync)
psycopg2.OperationalError: connection to server at "postgres" (172.18.0.4), port 5432 failed: FATAL:  password authentication failed for user "***"


The above exception was the direct cause of the following exception:

Traceback (most recent call last):
  File "/home/airflow/.local/lib/python3.9/site-packages/airflow/models/taskinstance.py", line 465, in _execute_task
    result = _execute_callable(context=context, **execute_callable_kwargs)
  File "/home/airflow/.local/lib/python3.9/site-packages/airflow/models/taskinstance.py", line 432, in _execute_callable
    return execute_callable(context=context, **execute_callable_kwargs)
  File "/home/airflow/.local/lib/python3.9/site-packages/airflow/models/baseoperator.py", line 400, in wrapper
    return func(self, *args, **kwargs)
  File "/home/airflow/.local/lib/python3.9/site-packages/airflow/operators/python.py", line 235, in execute
    return_value = self.execute_callable()
  File "/home/airflow/.local/lib/python3.9/site-packages/airflow/operators/python.py", line 252, in execute_callable
    return self.python_callable(*self.op_args, **self.op_kwargs)
  File "/opt/airflow/dags/etl_sales.py", line 37, in load_user_info_data_to_postgres
    df.to_sql(table_name, con=engine, if_exists='append', index=False)
  File "/home/airflow/.local/lib/python3.9/site-packages/pandas/util/_decorators.py", line 333, in wrapper
    return func(*args, **kwargs)
  File "/home/airflow/.local/lib/python3.9/site-packages/pandas/core/generic.py", line 3008, in to_sql
    return sql.to_sql(
  File "/home/airflow/.local/lib/python3.9/site-packages/pandas/io/sql.py", line 787, in to_sql
    with pandasSQL_builder(con, schema=schema, need_transaction=True) as pandas_sql:
  File "/home/airflow/.local/lib/python3.9/site-packages/pandas/io/sql.py", line 851, in pandasSQL_builder
    return SQLDatabase(con, schema, need_transaction)
  File "/home/airflow/.local/lib/python3.9/site-packages/pandas/io/sql.py", line 1576, in __init__
    con = self.exit_stack.enter_context(con.connect())
  File "/home/airflow/.local/lib/python3.9/site-packages/sqlalchemy/engine/base.py", line 3325, in connect
    return self._connection_cls(self, close_with_result=close_with_result)
  File "/home/airflow/.local/lib/python3.9/site-packages/sqlalchemy/engine/base.py", line 96, in __init__
    else engine.raw_connection()
  File "/home/airflow/.local/lib/python3.9/site-packages/sqlalchemy/engine/base.py", line 3404, in raw_connection
    return self._wrap_pool_connect(self.pool.connect, _connection)
  File "/home/airflow/.local/lib/python3.9/site-packages/sqlalchemy/engine/base.py", line 3374, in _wrap_pool_connect
    Connection._handle_dbapi_exception_noconnection(
  File "/home/airflow/.local/lib/python3.9/site-packages/sqlalchemy/engine/base.py", line 2208, in _handle_dbapi_exception_noconnection
    util.raise_(
  File "/home/airflow/.local/lib/python3.9/site-packages/sqlalchemy/util/compat.py", line 211, in raise_
    raise exception
  File "/home/airflow/.local/lib/python3.9/site-packages/sqlalchemy/engine/base.py", line 3371, in _wrap_pool_connect
    return fn()
  File "/home/airflow/.local/lib/python3.9/site-packages/sqlalchemy/pool/base.py", line 327, in connect
    return _ConnectionFairy._checkout(self)
  File "/home/airflow/.local/lib/python3.9/site-packages/sqlalchemy/pool/base.py", line 894, in _checkout
    fairy = _ConnectionRecord.checkout(pool)
  File "/home/airflow/.local/lib/python3.9/site-packages/sqlalchemy/pool/base.py", line 493, in checkout
    rec = pool._do_get()
  File "/home/airflow/.local/lib/python3.9/site-packages/sqlalchemy/pool/impl.py", line 146, in _do_get
    self._dec_overflow()
  File "/home/airflow/.local/lib/python3.9/site-packages/sqlalchemy/util/langhelpers.py", line 70, in __exit__
    compat.raise_(
  File "/home/airflow/.local/lib/python3.9/site-packages/sqlalchemy/util/compat.py", line 211, in raise_
    raise exception
  File "/home/airflow/.local/lib/python3.9/site-packages/sqlalchemy/pool/impl.py", line 143, in _do_get
    return self._create_connection()
  File "/home/airflow/.local/lib/python3.9/site-packages/sqlalchemy/pool/base.py", line 273, in _create_connection
    return _ConnectionRecord(self)
  File "/home/airflow/.local/lib/python3.9/site-packages/sqlalchemy/pool/base.py", line 388, in __init__
    self.__connect()
  File "/home/airflow/.local/lib/python3.9/site-packages/sqlalchemy/pool/base.py", line 691, in __connect
    pool.logger.debug("Error on connect(): %s", e)
  File "/home/airflow/.local/lib/python3.9/site-packages/sqlalchemy/util/langhelpers.py", line 70, in __exit__
    compat.raise_(
  File "/home/airflow/.local/lib/python3.9/site-packages/sqlalchemy/util/compat.py", line 211, in raise_
    raise exception
  File "/home/airflow/.local/lib/python3.9/site-packages/sqlalchemy/pool/base.py", line 686, in __connect
    self.dbapi_connection = connection = pool._invoke_creator(self)
  File "/home/airflow/.local/lib/python3.9/site-packages/sqlalchemy/engine/create.py", line 574, in connect
    return dialect.connect(*cargs, **cparams)
  File "/home/airflow/.local/lib/python3.9/site-packages/sqlalchemy/engine/default.py", line 598, in connect
    return self.dbapi.connect(*cargs, **cparams)
  File "/home/airflow/.local/lib/python3.9/site-packages/psycopg2/__init__.py", line 122, in connect
    conn = _connect(dsn, connection_factory=connection_factory, **kwasync)
sqlalchemy.exc.OperationalError: (psycopg2.OperationalError) connection to server at "postgres" (172.18.0.4), port 5432 failed: FATAL:  password authentication failed for user "***"

(Background on this error at: https://sqlalche.me/e/14/e3q8)
[2024-12-03T12:47:38.927+0000] {taskinstance.py:1205} INFO - Marking task as FAILED. dag_id=etl_process_dag, task_id=load_user_info_data, execution_date=20241203T124733, start_date=20241203T124738, end_date=20241203T124738
[2024-12-03T12:47:38.948+0000] {standard_task_runner.py:110} ERROR - Failed to execute job 48 for task load_user_info_data ((psycopg2.OperationalError) connection to server at "postgres" (172.18.0.4), port 5432 failed: FATAL:  password authentication failed for user "***"

(Background on this error at: https://sqlalche.me/e/14/e3q8); 3670)
[2024-12-03T12:47:39.003+0000] {local_task_job_runner.py:240} INFO - Task exited with return code 1
[2024-12-03T12:47:39.041+0000] {logging_mixin.py:188} WARNING - /home/***/.local/lib/python3.9/site-packages/***/models/baseoperator.py:1296 AirflowProviderDeprecationWarning: Call to deprecated class PostgresOperator. (Please use `***.providers.common.sql.operators.sql.SQLExecuteQueryOperator`.Also, you can provide `hook_params={'schema': <database>}`.)
[2024-12-03T12:47:39.061+0000] {taskinstance.py:3482} INFO - 0 downstream tasks scheduled from follow-on schedule check
[2024-12-03T12:47:39.066+0000] {local_task_job_runner.py:222} INFO - ::endgroup::
